<mujoco model="biped_s41">
  <compiler angle="radian" meshdir="../meshes/"/>
  <size njmax="500" nconmax="100" />

  <default>
    <joint limited='true'/>

    <default class='leg_joint_param'>
        <joint  damping="0.01" frictionloss="0.01" armature="0.01"/>
    </default>

  </default>

  <asset>
    <texture type="skybox" builtin="gradient" rgb1="0.4 0.6 0.8" width="128" height="128"/>
    <texture name="grid" type="2d" builtin="checker" rgb1=".1 .2 .3" rgb2=".2 .3 .4" width="300" height="300"/>
    <material name="grid" texture="grid" texrepeat="8 8" reflectance=".1"/>
    <mesh name="base_link" file="torso.STL"/>
    <mesh name="l_leg_roll" file="l_leg_roll.STL"/>
    <mesh name="l_leg_yaw" file="l_leg_yaw.STL"/>
    <mesh name="l_leg_pitch" file="l_leg_pitch.STL"/>
    <mesh name="l_knee" file="l_knee.STL"/>
    <mesh name="l_foot_pitch" file="l_foot_pitch.STL"/>
    <mesh name="l_foot_roll" file="l_foot_roll.STL"/>
    <mesh name="r_leg_roll" file="r_leg_roll.STL"/>
    <mesh name="r_leg_yaw" file="r_leg_yaw.STL"/>
    <mesh name="r_leg_pitch" file="r_leg_pitch.STL"/>
    <mesh name="r_knee" file="r_knee.STL"/>
    <mesh name="r_foot_pitch" file="r_foot_pitch.STL"/>
    <mesh name="r_foot_roll" file="r_foot_roll.STL"/>
    <mesh name="l_arm_pitch" file="l_arm_pitch.STL"/>
    <mesh name="l_arm_roll" file="l_arm_roll.STL"/>
    <mesh name="l_foream" file="l_foream.STL"/>
    <mesh name="r_arm_pitch" file="r_arm_pitch.STL"/>
    <mesh name="r_arm_roll" file="r_arm_roll.STL"/>
    <mesh name="r_foream" file="r_foream.STL"/>
  </asset>
  <worldbody>
    <body name="base_link" pos="0 0 0.78">
      <freejoint/>
      <inertial pos="-0.0177995 0.00029663 0.181764" quat="0.998463 -7.08433e-06 -0.0554125 -0.000904055" mass="25.1666" diaginertia="0.849687 0.737699 0.236205"/>
      <geom type="mesh" contype="0" conaffinity="0" group="1" density="0" rgba="1 1 1 1" mesh="base_link"/>
      <geom type="mesh" rgba="1 1 1 1" mesh="base_link"/>
      <site name="imu" pos="0 0 0"/>
      <body name="leg_l1_link" pos="-0.0024999 0.087 -0.066">
        <inertial pos="-0.00430148 -2.708e-05 -0.00851195" quat="0.00114226 0.692081 0.00279499 0.721814" mass="1.71093" diaginertia="0.00371121 0.00277272 0.00205799"/>
        <joint name="leg_l1_joint" pos="0 0 0" axis="1 0 0" range="-0.314159 0.663225" class="leg_joint_param" />
        <geom type="mesh" contype="0" conaffinity="0" group="1" density="0" rgba="1 1 1 1" mesh="l_leg_roll"/>
        <body name="leg_l2_link">
          <inertial pos="0 -0.0032256 -0.0908087" quat="0.769899 0.638166 1.50247e-05 -1.35996e-05" mass="0.557629" diaginertia="0.00213816 0.00140333 0.00117498"/>
          <joint name="leg_l2_joint" pos="0 0 0" axis="0 0 1" range="-0.872665 0.785398" class="leg_joint_param" />
          <geom type="mesh" contype="0" conaffinity="0" group="1" density="0" rgba="1 1 1 1" mesh="l_leg_yaw"/>
          <body name="leg_l3_link" pos="0 0 -0.1287">
            <inertial pos="0.00185677 0.0102346 -0.0855838" quat="0.724347 0.00513635 0.0261431 0.688921" mass="4.93577" diaginertia="0.0434466 0.0427748 0.0109324"/>
            <joint name="leg_l3_joint" pos="0 0 0" axis="0 1 0" range="-2.00713 1.5708" class="leg_joint_param" />
            <geom type="mesh" contype="0" conaffinity="0" group="1" density="0" rgba="1 1 1 1" mesh="l_leg_pitch"/>
            <body name="leg_l4_link" pos="0 0 -0.284">
              <inertial pos="0.00716677 -6.696e-05 -0.114819" quat="0.999988 0.000491325 0.000347396 0.0048566" mass="1.61275" diaginertia="0.011037 0.0109512 0.000872235"/>
              <joint name="leg_l4_joint" pos="0 0 0" axis="0 1 0" range="0 2.61799" class="leg_joint_param" />
              <geom type="mesh" contype="0" conaffinity="0" group="1" density="0" rgba="1 1 1 1" mesh="l_knee"/>
              <body name="leg_l5_link" pos="0 0 -0.346">
                <inertial pos="0 0 0" quat="0.5 0.5 -0.5 0.5" mass="0.0719352" diaginertia="1.218e-05 6.92e-06 6.92e-06"/>
                <joint name="leg_l5_joint" pos="0 0 0" axis="0 1 0" range="-0.785398 0.349066" class="leg_joint_param" />
                <geom type="mesh" contype="0" conaffinity="0" group="1" density="0" rgba="0.647059 0.619608 0.588235 1" mesh="l_foot_pitch"/>
                <body name="leg_l6_link">
                  <inertial pos="0.0373958 -2.2061e-06 -0.0389679" quat="-5.61629e-06 0.695245 1.1461e-05 0.718773" mass="0.501754" diaginertia="0.00177876 0.00163456 0.000397"/>
                  <joint name="leg_l6_joint" pos="0 0 0" axis="1 0 0" range="-0.261799 0.261799" class="leg_joint_param" />
                  <geom type="mesh" contype="0" conaffinity="0" group="1" density="0" rgba="1 1 1 1" mesh="l_foot_roll"/>
                  <geom size="0.005" pos="-0.07316 0.04773 -0.0593" contype="0" conaffinity="0" group="1" density="0" rgba="1 1 1 1"/>
                  <geom size="0.005" pos="-0.07316 0.04773 -0.0593" rgba="1 1 1 1"/>
                  <geom size="0.005" pos="-0.07316 -0.04773 -0.0593" contype="0" conaffinity="0" group="1" density="0" rgba="1 1 1 1"/>
                  <geom size="0.005" pos="-0.07316 -0.04773 -0.0593" rgba="1 1 1 1"/>
                  <geom size="0.005" pos="0.16902 0.04773 -0.0593" contype="0" conaffinity="0" group="1" density="0" rgba="1 1 1 1"/>
                  <geom size="0.005" pos="0.16902 0.04773 -0.0593" rgba="1 1 1 1"/>
                  <geom size="0.005" pos="0.16902 -0.04773 -0.0593" contype="0" conaffinity="0" group="1" density="0" rgba="1 1 1 1"/>
                  <geom size="0.005" pos="0.16902 -0.04773 -0.0593" rgba="1 1 1 1"/>
                  <site name="left_foot_site" pos="0 0 -0.055" size="0.01" />
                </body>
              </body>
            </body>
          </body>
        </body>
      </body>
      <body name="leg_r1_link" pos="-0.0024999 -0.087 -0.066">
        <inertial pos="-0.00430146 2.709e-05 -0.00851195" quat="-0.00114226 0.692081 -0.00279499 0.721814" mass="1.71093" diaginertia="0.00371121 0.00277272 0.00205799"/>
        <joint name="leg_r1_joint" pos="0 0 0" axis="1 0 0" range="-0.663225 0.314159" class="leg_joint_param" />
        <geom type="mesh" contype="0" conaffinity="0" group="1" density="0" rgba="1 1 1 1" mesh="r_leg_roll"/>
        <body name="leg_r2_link">
          <inertial pos="0 0.00322561 -0.0908087" quat="0.638166 0.769899 1.35996e-05 -1.50247e-05" mass="0.557629" diaginertia="0.00213816 0.00140333 0.00117498"/>
          <joint name="leg_r2_joint" pos="0 0 0" axis="0 0 1" range="-0.785398 0.872665" class="leg_joint_param" />
          <geom type="mesh" contype="0" conaffinity="0" group="1" density="0" rgba="1 1 1 1" mesh="r_leg_yaw"/>
          <body name="leg_r3_link" pos="0 0 -0.1287">
            <inertial pos="0.00185677 -0.0102346 -0.0855838" quat="0.714834 0.0057373 0.0258337 0.698793" mass="4.93577" diaginertia="0.0442361 0.0427757 0.010933"/>
            <joint name="leg_r3_joint" pos="0 0 0" axis="0 1 0" range="-2.00713 1.5708" class="leg_joint_param" />
            <geom type="mesh" contype="0" conaffinity="0" group="1" density="0" rgba="1 1 1 1" mesh="r_leg_pitch"/>
            <body name="leg_r4_link" pos="0 0 -0.284">
              <inertial pos="0.00716677 6.696e-05 -0.114819" quat="0.999988 0.000491325 0.000347396 0.0048566" mass="1.61275" diaginertia="0.011037 0.0109512 0.000872235"/>
              <joint name="leg_r4_joint" pos="0 0 0" axis="0 1 0" range="0 2.61799" class="leg_joint_param" />
              <geom type="mesh" contype="0" conaffinity="0" group="1" density="0" rgba="1 1 1 1" mesh="r_knee"/>
              <body name="leg_r5_link" pos="0 0 -0.346">
                <inertial pos="0 0 0" quat="0.5 0.5 -0.5 0.5" mass="0.0719352" diaginertia="1.218e-05 6.92e-06 6.92e-06"/>
                <joint name="leg_r5_joint" pos="0 0 0" axis="0 1 0" range="-0.785398 0.349066" class="leg_joint_param" />
                <geom type="mesh" contype="0" conaffinity="0" group="1" density="0" rgba="0.647059 0.619608 0.588235 1" mesh="r_foot_pitch"/>
                <body name="leg_r6_link">
                  <inertial pos="0.0373958 -2.2061e-06 -0.0389679" quat="-5.61629e-06 0.695245 1.1461e-05 0.718773" mass="0.501754" diaginertia="0.00177876 0.00163456 0.000397"/>
                  <joint name="leg_r6_joint" pos="0 0 0" axis="1 0 0" range="-0.261799 0.261799" class="leg_joint_param" />
                  <geom type="mesh" contype="0" conaffinity="0" group="1" density="0" rgba="1 1 1 1" mesh="r_foot_roll"/>
                  <geom size="0.005" pos="-0.07316 0.04773 -0.0593" contype="0" conaffinity="0" group="1" density="0" rgba="1 1 1 1"/>
                  <geom size="0.005" pos="-0.07316 0.04773 -0.0593" rgba="1 1 1 1"/>
                  <geom size="0.005" pos="-0.07316 -0.04773 -0.0593" contype="0" conaffinity="0" group="1" density="0" rgba="1 1 1 1"/>
                  <geom size="0.005" pos="-0.07316 -0.04773 -0.0593" rgba="1 1 1 1"/>
                  <geom size="0.005" pos="0.16902 0.04773 -0.0593" contype="0" conaffinity="0" group="1" density="0" rgba="1 1 1 1"/>
                  <geom size="0.005" pos="0.16902 0.04773 -0.0593" rgba="1 1 1 1"/>
                  <geom size="0.005" pos="0.16902 -0.04773 -0.0593" contype="0" conaffinity="0" group="1" density="0" rgba="1 1 1 1"/>
                  <geom size="0.005" pos="0.16902 -0.04773 -0.0593" rgba="1 1 1 1"/>
                  <site name="right_foot_site" pos="0 0 -0.055" size="0.01" />
                </body>
              </body>
            </body>
          </body>
        </body>
      </body>
      <body name="zarm_l1_link" pos="-0.0174999 0.2757 0.4245">
        <inertial pos="0.00277 0.01426 -7e-05" quat="0.494875 0.505073 -0.494875 0.505073" mass="0.78" diaginertia="0.0011 0.0010002 0.000509796"/>
        <joint name="zarm_l1_joint" pos="0 0 0" axis="0 1 0" range="-3.14159 1.5708" damping='0.1' />
        <geom type="mesh" contype="0" conaffinity="0" group="1" density="0" rgba="1 1 1 1" mesh="l_arm_pitch"/>
        <body name="zarm_l2_link">
          <inertial pos="0.01059 0.00151 0.19694" quat="0.660503 0.0308892 0.0373308 0.749259" mass="1.012" diaginertia="0.00761284 0.0075292 0.000907966"/>
          <joint name="zarm_l2_joint" pos="0 0 0" axis="1 0 0" range="-0.349066 2.0944" damping='0.1' />
          <geom type="mesh" contype="0" conaffinity="0" group="1" density="0" rgba="1 1 1 1" mesh="l_arm_roll"/>
          <body name="zarm_l3_link" pos="0.02 0 -0.254">
            <inertial pos="-0.01915 -0.00015 0.22036" quat="0.999985 -0.000893461 -0.0053477 -0.00106095" mass="0.335" diaginertia="0.00580064 0.00575002 0.00018934"/>
            <joint name="zarm_l3_joint" pos="0 0 0" axis="0 1 0" range="-2.61799 0" damping='0.1' />
            <geom type="mesh" contype="0" conaffinity="0" group="1" density="0" rgba="1 1 1 1" mesh="l_foream"/>
          </body>
        </body>
      </body>
      <body name="zarm_r1_link" pos="-0.0174999 -0.2757 0.4245">
        <inertial pos="-0.001 0.03434 7e-05" quat="0.517419 0.481952 -0.517419 0.481952" mass="0.78" diaginertia="0.00106 0.000962843 0.000397157"/>
        <joint name="zarm_r1_joint" pos="0 0 0" axis="0 1 0" range="-3.14159 1.5708" damping='0.1' />
        <geom type="mesh" contype="0" conaffinity="0" group="1" density="0" rgba="1 1 1 1" mesh="r_arm_pitch" />
        <body name="zarm_r2_link">
          <inertial pos="0.00556 -0.0019 -0.1847" quat="0.728188 -0.0317154 -0.0216898 0.6843" mass="1.012" diaginertia="0.00573157 0.00566683 0.000851598"/>
          <joint name="zarm_r2_joint" pos="0 0 0" axis="1 0 0" range="-2.0944 0.349066" damping='0.1' />
          <geom type="mesh" contype="0" conaffinity="0" group="1" density="0" rgba="1 1 1 1" mesh="r_arm_roll"/>
          <body name="zarm_r3_link" pos="0.02 0 -0.254">
            <inertial pos="-0.01754 0 -0.13095" quat="0.999959 0 0.00903986 0" mass="0.335" diaginertia="0.00814253 0.00795 0.000397469"/>
            <joint name="zarm_r3_joint" pos="0 0 0" axis="0 1 0" range="-2.61799 0" damping='0.1' />
            <geom type="mesh" contype="0" conaffinity="0" group="1" density="0" rgba="1 1 1 1" mesh="r_foream"/>
          </body>
        </body>
      </body>
    </body>
  </worldbody>
  <actuator>
        <motor gear="1" joint="leg_l1_joint" name="leg_l1_motor" ctrllimited="true"  ctrlrange='-180 180'/>
        <motor gear="1" joint="leg_l2_joint" name="leg_l2_motor" ctrllimited="true"  ctrlrange='-100 100'/>
        <motor gear="1" joint="leg_l3_joint" name="leg_l3_motor" ctrllimited="true"  ctrlrange='-100 100'/>
        <motor gear="1" joint="leg_l4_joint" name="leg_l4_motor" ctrllimited="true"  ctrlrange='-180 180'/>
        <motor gear="1" joint="leg_l5_joint" name="leg_l5_motor" ctrllimited="true"  ctrlrange='-36 36'/>
        <motor gear="1" joint="leg_l6_joint" name="leg_l6_motor" ctrllimited="true"  ctrlrange='-36 36'/>

        <motor gear="1" joint="leg_r1_joint" name="leg_r1_motor" ctrllimited="true"  ctrlrange='-180 180'/>
        <motor gear="1" joint="leg_r2_joint" name="leg_r2_motor" ctrllimited="true"  ctrlrange='-100 100'/>
        <motor gear="1" joint="leg_r3_joint" name="leg_r3_motor" ctrllimited="true"  ctrlrange='-100 100'/>
        <motor gear="1" joint="leg_r4_joint" name="leg_r4_motor" ctrllimited="true"  ctrlrange='-180 180'/>
        <motor gear="1" joint="leg_r5_joint" name="leg_r5_motor" ctrllimited="true"  ctrlrange='-36 36'/>
        <motor gear="1" joint="leg_r6_joint" name="leg_r6_motor" ctrllimited="true"  ctrlrange='-36 36'/>

        <motor gear="1" joint="zarm_l1_joint" name="zarm_l1_motor" ctrllimited="true"  ctrlrange='-100 100'/>
        <motor gear="1" joint="zarm_l2_joint" name="zarm_l2_motor" ctrllimited="true"  ctrlrange='-50 50'/>
        <motor gear="1" joint="zarm_l3_joint" name="zarm_l3_motor" ctrllimited="true"  ctrlrange='-50 50'/>

        <motor gear="1" joint="zarm_r1_joint" name="zarm_r1_motor" ctrllimited="true"  ctrlrange='-100 100'/>
        <motor gear="1" joint="zarm_r2_joint" name="zarm_r2_motor" ctrllimited="true"  ctrlrange='-50 50'/>
        <motor gear="1" joint="zarm_r3_joint" name="zarm_r3_motor" ctrllimited="true"  ctrlrange='-50 50'/>
  </actuator>
  <sensor>
      <framequat     name='orientation' objtype='site' objname='imu'/>
      <framepos      name='position' objtype='site' objname='imu'/>
      <gyro          name='angular-velocity'    site='imu' />
      <velocimeter   name='linear-velocity'     site='imu' />
      <accelerometer name='linear-acceleration' site='imu' />
      <magnetometer  name='magnetometer'        site='imu'/>

      <accelerometer name="BodyAcc" site="imu"/>
      <velocimeter name="BodyVel" site="imu"/>
      <gyro name="BodyGyro" site="imu"/>
      <framepos name="BodyPos" objtype="site" objname="imu"/>
      <framequat name="BodyQuat" objtype="site" objname="imu"/>

      <jointpos name="leg_l1_pos" joint="leg_l1_joint"/>
      <jointpos name="leg_l2_pos" joint="leg_l2_joint"/>
      <jointpos name="leg_l3_pos" joint="leg_l3_joint"/>
      <jointpos name="leg_l4_pos" joint="leg_l4_joint"/>
      <jointpos name="leg_l5_pos" joint="leg_l5_joint"/>
      <jointpos name="leg_l6_pos" joint="leg_l6_joint"/>

      <jointpos name="leg_r1_pos" joint="leg_r1_joint"/>
      <jointpos name="leg_r2_pos" joint="leg_r2_joint"/>
      <jointpos name="leg_r3_pos" joint="leg_r3_joint"/>
      <jointpos name="leg_r4_pos" joint="leg_r4_joint"/>
      <jointpos name="leg_r5_pos" joint="leg_r5_joint"/>
      <jointpos name="leg_r6_pos" joint="leg_r6_joint"/>

      <force name="left_foot_force" site="left_foot_site"/>
      <force name="right_foot_force" site="right_foot_site"/>
      <framepos name="left_foot_pos" objtype="site" objname="left_foot_site"/>
      <framepos name="right_foot_pos" objtype="site" objname="right_foot_site"/>
      <!-- <framevel name="left_foot_vel" objtype="site" objname="left_foot_site"/>
      <framevel name="right_foot_vel" objtype="site" objname="right_foot_site"/> -->

      <jointvel name="leg_l1_vel" joint="leg_l1_joint"/>
      <jointvel name="leg_l2_vel" joint="leg_l2_joint"/>
      <jointvel name="leg_l3_vel" joint="leg_l3_joint"/>
      <jointvel name="leg_l4_vel" joint="leg_l4_joint"/>
      <jointvel name="leg_l5_vel" joint="leg_l5_joint"/>
      <jointvel name="leg_l6_vel" joint="leg_l6_joint"/>

      <jointvel name="leg_r1_vel" joint="leg_r1_joint"/>
      <jointvel name="leg_r2_vel" joint="leg_r2_joint"/>
      <jointvel name="leg_r3_vel" joint="leg_r3_joint"/>
      <jointvel name="leg_r4_vel" joint="leg_r4_joint"/>
      <jointvel name="leg_r5_vel" joint="leg_r5_joint"/>
      <jointvel name="leg_r6_vel" joint="leg_r6_joint"/>

      <!-- <jointvel name="zarm_l1_vel" joint="zarm_l1_joint"/>
      <jointvel name="zarm_l2_vel" joint="zarm_l2_joint"/>
      <jointvel name="zarm_l3_vel" joint="zarm_l3_joint"/>

      <jointvel name="zarm_r1_vel" joint="zarm_r1_joint"/>
      <jointvel name="zarm_r2_vel" joint="zarm_r2_joint"/>
      <jointvel name="zarm_r3_vel" joint="zarm_r3_joint"/> -->
  </sensor>
</mujoco>
